[2025-02-16T12:07:02.030+0000] {taskinstance.py:1159} INFO - Dependencies all met for dep_context=non-requeueable deps ti=<TaskInstance: kafka_spark_dag.pyspark_consumer manual__2025-02-16T12:06:16.381853+00:00 [queued]>
[2025-02-16T12:07:02.059+0000] {taskinstance.py:1159} INFO - Dependencies all met for dep_context=requeueable deps ti=<TaskInstance: kafka_spark_dag.pyspark_consumer manual__2025-02-16T12:06:16.381853+00:00 [queued]>
[2025-02-16T12:07:02.060+0000] {taskinstance.py:1361} INFO - Starting attempt 1 of 2
[2025-02-16T12:07:02.098+0000] {taskinstance.py:1382} INFO - Executing <Task(DockerOperator): pyspark_consumer> on 2025-02-16 12:06:16.381853+00:00
[2025-02-16T12:07:02.113+0000] {standard_task_runner.py:57} INFO - Started process 1930 to run task
[2025-02-16T12:07:02.157+0000] {standard_task_runner.py:84} INFO - Running: ['airflow', 'tasks', 'run', 'kafka_spark_dag', 'pyspark_consumer', 'manual__2025-02-16T12:06:16.381853+00:00', '--job-id', '13', '--raw', '--subdir', 'DAGS_FOLDER/dag_kafka_spark.py', '--cfg-path', '/tmp/tmpgpr6uygz']
[2025-02-16T12:07:02.168+0000] {standard_task_runner.py:85} INFO - Job 13: Subtask pyspark_consumer
[2025-02-16T12:07:02.616+0000] {task_command.py:416} INFO - Running <TaskInstance: kafka_spark_dag.pyspark_consumer manual__2025-02-16T12:06:16.381853+00:00 [running]> on host 00de9d446011
[2025-02-16T12:07:03.056+0000] {taskinstance.py:1662} INFO - Exporting env vars: AIRFLOW_CTX_DAG_OWNER='airflow' AIRFLOW_CTX_DAG_ID='kafka_spark_dag' AIRFLOW_CTX_TASK_ID='pyspark_consumer' AIRFLOW_CTX_EXECUTION_DATE='2025-02-16T12:06:16.381853+00:00' AIRFLOW_CTX_TRY_NUMBER='1' AIRFLOW_CTX_DAG_RUN_ID='manual__2025-02-16T12:06:16.381853+00:00'
[2025-02-16T12:07:03.203+0000] {docker.py:470} INFO - Pulling docker image Mohamed/spark:latest
[2025-02-16T12:07:03.233+0000] {taskinstance.py:1937} ERROR - Task failed with exception
Traceback (most recent call last):
  File "/home/airflow/.local/lib/python3.8/site-packages/docker/api/client.py", line 268, in _raise_for_status
    response.raise_for_status()
  File "/home/airflow/.local/lib/python3.8/site-packages/requests/models.py", line 1021, in raise_for_status
    raise HTTPError(http_error_msg, response=self)
requests.exceptions.HTTPError: 500 Server Error: Internal Server Error for url: http://docker-proxy:2375/v1.47/images/create?tag=latest&fromImage=Mohamed%2Fspark

The above exception was the direct cause of the following exception:

Traceback (most recent call last):
  File "/home/airflow/.local/lib/python3.8/site-packages/airflow/providers/docker/operators/docker.py", line 472, in execute
    for output in self.cli.pull(self.image, stream=True, decode=True):
  File "/home/airflow/.local/lib/python3.8/site-packages/docker/api/image.py", line 429, in pull
    self._raise_for_status(response)
  File "/home/airflow/.local/lib/python3.8/site-packages/docker/api/client.py", line 270, in _raise_for_status
    raise create_api_error_from_http_exception(e) from e
  File "/home/airflow/.local/lib/python3.8/site-packages/docker/errors.py", line 39, in create_api_error_from_http_exception
    raise cls(e, response=response, explanation=explanation) from e
docker.errors.APIError: 500 Server Error for http://docker-proxy:2375/v1.47/images/create?tag=latest&fromImage=Mohamed%2Fspark: Internal Server Error ("Get "https://Mohamed/v2/": dial tcp: lookup Mohamed on 127.0.0.53:53: server misbehaving")
[2025-02-16T12:07:03.301+0000] {taskinstance.py:1400} INFO - Marking task as UP_FOR_RETRY. dag_id=kafka_spark_dag, task_id=pyspark_consumer, execution_date=20250216T120616, start_date=20250216T120702, end_date=20250216T120703
[2025-02-16T12:07:03.368+0000] {standard_task_runner.py:104} ERROR - Failed to execute job 13 for task pyspark_consumer (500 Server Error for http://docker-proxy:2375/v1.47/images/create?tag=latest&fromImage=Mohamed%2Fspark: Internal Server Error ("Get "https://Mohamed/v2/": dial tcp: lookup Mohamed on 127.0.0.53:53: server misbehaving"); 1930)
[2025-02-16T12:07:03.418+0000] {local_task_job_runner.py:228} INFO - Task exited with return code 1
[2025-02-16T12:07:03.473+0000] {taskinstance.py:2778} INFO - 0 downstream tasks scheduled from follow-on schedule check
